<?xml version="1.0" encoding="UTF-8"?>
<testsuite errors="1" failures="0" name="unittest.loader._FailedTest-20190209194121" skipped="0" tests="1" time="0.000" timestamp="2019-02-09T19:41:21">
	<testcase classname="unittest.loader._FailedTest" name="mypybuilder_tests" time="0.000" timestamp="2019-02-09T19:41:21">
		<error message="Failed to import test module: mypybuilder_tests
Traceback (most recent call last):
  File &quot;c:\users\felic\appdata\local\programs\python\python35\lib\unittest\loader.py&quot;, line 153, in loadTestsFromName
    module = __import__(module_name)
  File &quot;c:\users\felic\documents\datascience-master\1_semester\softwareengineering\pet-project\mypybuilder\src\unittest\python\mypybuilder_tests.py&quot;, line 3, in &lt;module&gt;
    from mock import Mock
ImportError: No module named 'mock'
" type="ImportError">
<![CDATA[ImportError: Failed to import test module: mypybuilder_tests
Traceback (most recent call last):
  File "c:\users\felic\appdata\local\programs\python\python35\lib\unittest\loader.py", line 153, in loadTestsFromName
    module = __import__(module_name)
  File "c:\users\felic\documents\datascience-master\1_semester\softwareengineering\pet-project\mypybuilder\src\unittest\python\mypybuilder_tests.py", line 3, in <module>
    from mock import Mock
ImportError: No module named 'mock'

]]>		</error>
	</testcase>
	<system-out>
<![CDATA[]]>	</system-out>
	<system-err>
<![CDATA[]]>	</system-err>
</testsuite>
